2016-03-25 22:19:56,619 : INFO : Machine : Mission Pinball Framework v0.30.0.dev801
2016-03-25 22:19:56,619 : INFO : Machine : Loading config from original files
2016-03-25 22:19:56,699 : INFO : Machine : Machine config file #1: /Users/gabe/Dropbox/Pinball/Gabe/bnd/config/config
2016-03-25 22:19:56,842 : INFO : Machine : Config file cache created: /Users/gabe/Dropbox/Pinball/Gabe/bnd/__mpfcache__/config_config.p
2016-03-25 22:19:56,858 : INFO : FAST : Configuring FAST hardware.
2016-03-25 22:19:56,858 : INFO : Machine : Loading core modules...
2016-03-25 22:19:57,025 : INFO : FAST : Configuring FAST Controller for FAST IO boards.
2016-03-25 22:19:57,025 : INFO : FAST : Connecting to /dev/tty.usbserial-141C at 921600bps
2016-03-25 22:19:58,544 : INFO : FAST : Received ID acknowledgement. Processor: RGB, Board: FP-CPU-002-2, Firmware: 01.00
2016-03-25 22:19:58,545 : INFO : FAST : Connecting to /dev/tty.usbserial-141B at 921600bps
2016-03-25 22:19:58,545 : ERROR : root : could not open port /dev/tty.usbserial-141B: [Errno 16] Resource busy: '/dev/tty.usbserial-141B'
Traceback (most recent call last):
  File "/Applications/Kivy.app/Contents/Frameworks/python/3.5.0/lib/python3.5/site-packages/serial/serialposix.py", line 275, in open
    self.fd = os.open(self.portstr, os.O_RDWR|os.O_NOCTTY|os.O_NONBLOCK)
OSError: [Errno 16] Resource busy: '/dev/tty.usbserial-141B'

During handling of the above exception, another exception occurred:

Traceback (most recent call last):
  File "/Users/gabe/pinball/mpf30/mpf/commands/core.py", line 135, in __init__
    MachineController(mpf_path, machine_path, vars(args)).run()
  File "/Users/gabe/pinball/mpf30/mpf/core/machine.py", line 104, in __init__
    self._initialize_platforms()
  File "/Users/gabe/pinball/mpf30/mpf/core/machine.py", line 141, in _initialize_platforms
    platform.initialize()
  File "/Users/gabe/pinball/mpf30/mpf/platforms/fast.py", line 284, in initialize
    self._connect_to_hardware()
  File "/Users/gabe/pinball/mpf30/mpf/platforms/fast.py", line 318, in _connect_to_hardware
    send_queue=queue.Queue(), receive_queue=self.receive_queue))
  File "/Users/gabe/pinball/mpf30/mpf/platforms/fast.py", line 1257, in __init__
    timeout=1, writeTimeout=0)
  File "/Applications/Kivy.app/Contents/Frameworks/python/3.5.0/lib/python3.5/site-packages/serial/serialutil.py", line 261, in __init__
    self.open()
  File "/Applications/Kivy.app/Contents/Frameworks/python/3.5.0/lib/python3.5/site-packages/serial/serialposix.py", line 278, in open
    raise SerialException("could not open port %s: %s" % (self._port, msg))
serial.serialutil.SerialException: could not open port /dev/tty.usbserial-141B: [Errno 16] Resource busy: '/dev/tty.usbserial-141B'
