2016-03-11 14:58:24,181 : INFO : Machine : Mission Pinball Framework v0.30.0.dev615
2016-03-11 14:58:24,181 : INFO : Machine : Loading config from original files
2016-03-11 14:58:24,234 : INFO : Machine : Machine config file #1: /Users/gabe/pinball/bnd/config/config
2016-03-11 14:58:24,359 : INFO : Machine : Config file cache created: /Users/gabe/pinball/bnd/__mpfcache__/config_config.p
2016-03-11 14:58:24,389 : INFO : FAST : Configuring FAST hardware.
2016-03-11 14:58:24,389 : INFO : Machine : Loading core modules...
2016-03-11 14:58:24,593 : INFO : FAST : Configuring FAST Controller for FAST IO boards.
2016-03-11 14:58:24,593 : INFO : FAST : Connecting to /dev/tty.usbserial-141C at 921600bps
2016-03-11 14:58:24,594 : ERROR : root : [Errno 2] could not open port /dev/tty.usbserial-141C: [Errno 2] No such file or directory: '/dev/tty.usbserial-141C'
Traceback (most recent call last):
  File "/Applications/Kivy.app/Contents/Frameworks/python/3.5.0/lib/python3.5/site-packages/serial/serialposix.py", line 291, in open
    self.fd = os.open(self.portstr, os.O_RDWR | os.O_NOCTTY | os.O_NONBLOCK)
FileNotFoundError: [Errno 2] No such file or directory: '/dev/tty.usbserial-141C'

During handling of the above exception, another exception occurred:

Traceback (most recent call last):
  File "/Users/gabe/pinball/mpf30/mpf/commands/core.py", line 135, in __init__
    MachineController(mpf_path, machine_path, vars(args)).run()
  File "/Users/gabe/pinball/mpf30/mpf/core/machine.py", line 120, in __init__
    platform.initialize()
  File "/Users/gabe/pinball/mpf30/mpf/platforms/fast.py", line 284, in initialize
    self._connect_to_hardware()
  File "/Users/gabe/pinball/mpf30/mpf/platforms/fast.py", line 318, in _connect_to_hardware
    send_queue=queue.Queue(), receive_queue=self.receive_queue))
  File "/Users/gabe/pinball/mpf30/mpf/platforms/fast.py", line 1244, in __init__
    timeout=1, writeTimeout=0)
  File "/Applications/Kivy.app/Contents/Frameworks/python/3.5.0/lib/python3.5/site-packages/serial/serialutil.py", line 180, in __init__
    self.open()
  File "/Applications/Kivy.app/Contents/Frameworks/python/3.5.0/lib/python3.5/site-packages/serial/serialposix.py", line 294, in open
    raise SerialException(msg.errno, "could not open port %s: %s" % (self._port, msg))
serial.serialutil.SerialException: [Errno 2] could not open port /dev/tty.usbserial-141C: [Errno 2] No such file or directory: '/dev/tty.usbserial-141C'
