2016-05-13 23:38:29,807 : INFO : Machine : Mission Pinball Framework Core Engine v0.30.0.dev1482
2016-05-13 23:38:29,808 : INFO : Machine : Machine path: /Users/gabe/Dropbox/Pinball/Gabe/bnd
2016-05-13 23:38:30,031 : INFO : Machine : Loading cached config: /var/folders/c1/z5pg47y54_s14cd2m1zmk1kc0000gn/T/db0cb78b77a969ed262a283d7c7743faconfig
2016-05-13 23:38:30,034 : INFO : Machine : Starting clock at 30.0Hz
2016-05-13 23:38:30,065 : INFO : FAST : Configuring FAST hardware.
2016-05-13 23:38:30,065 : INFO : Machine : Loading core modules...
2016-05-13 23:38:30,078 : ERROR : root : [Errno 2] could not open port /dev/tty.usbmodem00153811: [Errno 2] No such file or directory: '/dev/tty.usbmodem00153811'
Traceback (most recent call last):
  File "/Applications/MPF.app/Contents/Frameworks/python/3.5.0/lib/python3.5/site-packages/serial/serialposix.py", line 291, in open
    self.fd = os.open(self.portstr, os.O_RDWR | os.O_NOCTTY | os.O_NONBLOCK)
FileNotFoundError: [Errno 2] No such file or directory: '/dev/tty.usbmodem00153811'

During handling of the above exception, another exception occurred:

Traceback (most recent call last):
  File "/Applications/MPF.app/Contents/Frameworks/python/3.5.0/lib/python3.5/site-packages/mpf/commands/game.py", line 130, in __init__
    MachineController(mpf_path, machine_path, vars(args)).run()
  File "/Applications/MPF.app/Contents/Frameworks/python/3.5.0/lib/python3.5/site-packages/mpf/core/machine.py", line 120, in __init__
    self._initialize_platforms()
  File "/Applications/MPF.app/Contents/Frameworks/python/3.5.0/lib/python3.5/site-packages/mpf/core/machine.py", line 178, in _initialize_platforms
    platform.initialize()
  File "/Applications/MPF.app/Contents/Frameworks/python/3.5.0/lib/python3.5/site-packages/mpf/platforms/pololu_maestro.py", line 41, in initialize
    self.serial = serial.Serial(self.platform.config['port'])
  File "/Applications/MPF.app/Contents/Frameworks/python/3.5.0/lib/python3.5/site-packages/serial/serialutil.py", line 180, in __init__
    self.open()
  File "/Applications/MPF.app/Contents/Frameworks/python/3.5.0/lib/python3.5/site-packages/serial/serialposix.py", line 294, in open
    raise SerialException(msg.errno, "could not open port %s: %s" % (self._port, msg))
serial.serialutil.SerialException: [Errno 2] could not open port /dev/tty.usbmodem00153811: [Errno 2] No such file or directory: '/dev/tty.usbmodem00153811'
