2016-05-13 23:39:31,257 : INFO : Machine : Mission Pinball Framework Core Engine v0.30.0.dev1482
2016-05-13 23:39:31,258 : INFO : Machine : Machine path: /Users/gabe/Dropbox/Pinball/Gabe/bnd
2016-05-13 23:39:31,485 : INFO : Machine : Loading config from original files
2016-05-13 23:39:31,541 : INFO : Machine : Machine config file #1: /Users/gabe/Dropbox/Pinball/Gabe/bnd/config/config
2016-05-13 23:39:31,672 : INFO : Machine : Config file cache created: /var/folders/c1/z5pg47y54_s14cd2m1zmk1kc0000gn/T/db0cb78b77a969ed262a283d7c7743faconfig
2016-05-13 23:39:31,673 : INFO : Machine : Starting clock at 30.0Hz
2016-05-13 23:39:31,686 : INFO : FAST : Configuring FAST hardware.
2016-05-13 23:39:31,687 : INFO : Machine : Loading core modules...
2016-05-13 23:39:31,698 : INFO : FAST : Configuring FAST Controller for FAST IO boards.
2016-05-13 23:39:31,698 : INFO : FAST : Connecting to /dev/tty.usbserial-141C at 921600bps
2016-05-13 23:39:33,215 : INFO : FAST : Received ID acknowledgement. Processor: RGB, Board: FP-CPU-002-2, Firmware: 01.00
2016-05-13 23:39:33,216 : INFO : FAST : Connecting to /dev/tty.usbserial-141B at 921600bps
2016-05-13 23:39:34,733 : INFO : FAST : Received ID acknowledgement. Processor: NET, Board: FP-CPU-002-2, Firmware: 01.00
2016-05-13 23:39:34,750 : INFO : FAST : Fast IO Board 00: Model: FP-I/O-3208-2, Firmware: 01.00, Switches: 32, Drivers: 8
2016-05-13 23:39:34,766 : INFO : FAST : Fast IO Board 01: Model: FP-I/O-3208-2, Firmware: 01.00, Switches: 32, Drivers: 8
2016-05-13 23:39:34,766 : INFO : FAST : Fast IO Board 02: Model: FP-I/O-1616-2, Firmware: 01.00, Switches: 16, Drivers: 16
2016-05-13 23:39:34,800 : ERROR : root : [Errno 16] could not open port /dev/tty.usbmodem00153813: [Errno 16] Resource busy: '/dev/tty.usbmodem00153813'
Traceback (most recent call last):
  File "/Applications/MPF.app/Contents/Frameworks/python/3.5.0/lib/python3.5/site-packages/serial/serialposix.py", line 291, in open
    self.fd = os.open(self.portstr, os.O_RDWR | os.O_NOCTTY | os.O_NONBLOCK)
OSError: [Errno 16] Resource busy: '/dev/tty.usbmodem00153813'

During handling of the above exception, another exception occurred:

Traceback (most recent call last):
  File "/Applications/MPF.app/Contents/Frameworks/python/3.5.0/lib/python3.5/site-packages/mpf/commands/game.py", line 130, in __init__
    MachineController(mpf_path, machine_path, vars(args)).run()
  File "/Applications/MPF.app/Contents/Frameworks/python/3.5.0/lib/python3.5/site-packages/mpf/core/machine.py", line 120, in __init__
    self._initialize_platforms()
  File "/Applications/MPF.app/Contents/Frameworks/python/3.5.0/lib/python3.5/site-packages/mpf/core/machine.py", line 178, in _initialize_platforms
    platform.initialize()
  File "/Applications/MPF.app/Contents/Frameworks/python/3.5.0/lib/python3.5/site-packages/mpf/platforms/pololu_maestro.py", line 41, in initialize
    self.serial = serial.Serial(self.platform.config['port'])
  File "/Applications/MPF.app/Contents/Frameworks/python/3.5.0/lib/python3.5/site-packages/serial/serialutil.py", line 180, in __init__
    self.open()
  File "/Applications/MPF.app/Contents/Frameworks/python/3.5.0/lib/python3.5/site-packages/serial/serialposix.py", line 294, in open
    raise SerialException(msg.errno, "could not open port %s: %s" % (self._port, msg))
serial.serialutil.SerialException: [Errno 16] could not open port /dev/tty.usbmodem00153813: [Errno 16] Resource busy: '/dev/tty.usbmodem00153813'
