2016-06-17 17:49:03,882 : INFO : Machine : Mission Pinball Framework Core Engine v0.30.0.dev1800
2016-06-17 17:49:03,883 : INFO : Machine : Machine path: /Users/gabe/Dropbox/Pinball/Gabe/bnd
2016-06-17 17:49:04,095 : INFO : Machine : Loading config from original files
2016-06-17 17:49:04,137 : INFO : Machine : Machine config file #1: /Users/gabe/Dropbox/Pinball/Gabe/bnd/config/config
2016-06-17 17:49:04,310 : INFO : Machine : Config file cache created: /var/folders/c1/z5pg47y54_s14cd2m1zmk1kc0000gn/T/db0cb78b77a969ed262a283d7c7743faconfig
2016-06-17 17:49:04,310 : INFO : Machine : Starting clock at 30.0Hz
2016-06-17 17:49:04,323 : INFO : FAST : Connecting to /dev/tty.usbserial-141C at 921600bps
2016-06-17 17:49:05,844 : INFO : FAST : Connecting to /dev/tty.usbserial-141B at 921600bps
2016-06-17 17:49:07,467 : ERROR : ConfigProcessor : Your config contains a value for the setting "shots:right_lane:leds", but this is not a valid setting name.
2016-06-17 17:49:07,468 : ERROR : root : Your config contains a value for the setting "shots:right_lane:leds", but this is not a valid setting name.
Traceback (most recent call last):
  File "/Applications/MPF.app/Contents/Frameworks/python/3.5.0/lib/python3.5/site-packages/mpf/commands/game.py", line 130, in __init__
    MachineController(mpf_path, machine_path, vars(args)).run()
  File "/Applications/MPF.app/Contents/Frameworks/python/3.5.0/lib/python3.5/site-packages/mpf/core/machine.py", line 127, in __init__
    self._run_init_phases()
  File "/Applications/MPF.app/Contents/Frameworks/python/3.5.0/lib/python3.5/site-packages/mpf/core/machine.py", line 144, in _run_init_phases
    self.events.process_event_queue()
  File "/Applications/MPF.app/Contents/Frameworks/python/3.5.0/lib/python3.5/site-packages/mpf/core/events.py", line 481, in process_event_queue
    **event[3])
  File "/Applications/MPF.app/Contents/Frameworks/python/3.5.0/lib/python3.5/site-packages/mpf/core/events.py", line 416, in _process_event
    result = handler[0](**merged_kwargs)
  File "/Applications/MPF.app/Contents/Frameworks/python/3.5.0/lib/python3.5/site-packages/mpf/core/device_manager.py", line 59, in _load_device_modules
    self.load_devices_config(validate=True)
  File "/Applications/MPF.app/Contents/Frameworks/python/3.5.0/lib/python3.5/site-packages/mpf/core/device_manager.py", line 104, in load_devices_config
    config[device_name] = collection[device_name].validate_and_parse_config(config[device_name], False)
  File "/Applications/MPF.app/Contents/Frameworks/python/3.5.0/lib/python3.5/site-packages/mpf/core/device.py", line 78, in validate_and_parse_config
    self.config_section, config, self.name)
  File "/Applications/MPF.app/Contents/Frameworks/python/3.5.0/lib/python3.5/site-packages/mpf/core/config_validator.py", line 1257, in validate_config
    validation_failure_info)
  File "/Applications/MPF.app/Contents/Frameworks/python/3.5.0/lib/python3.5/site-packages/mpf/core/config_validator.py", line 1390, in check_for_invalid_sections
    'setting "' + path_string + '", but this is not a valid '
AssertionError: Your config contains a value for the setting "shots:right_lane:leds", but this is not a valid setting name.
