2016-03-11 15:14:12,370 : INFO : Machine : Mission Pinball Framework v0.30.0.dev615
2016-03-11 15:14:12,371 : INFO : Machine : Loading cached config: /Users/gabe/pinball/bnd/__mpfcache__/config_config.p
2016-03-11 15:14:12,388 : INFO : FAST : Configuring FAST hardware.
2016-03-11 15:14:12,388 : INFO : Machine : Loading core modules...
2016-03-11 15:14:12,556 : INFO : FAST : Configuring FAST Controller for FAST IO boards.
2016-03-11 15:14:12,556 : INFO : FAST : Connecting to /dev/tty.usbserial-141C at 921600bps
2016-03-11 15:14:15,061 : INFO : FAST : Received ID acknowledgement. Processor: RGB, Board: FP-CPU-002-2, Firmware: 00.88
2016-03-11 15:14:15,062 : INFO : FAST : Connecting to /dev/tty.usbserial-141A at 921600bps
2016-03-11 15:14:17,569 : INFO : FAST : Received ID acknowledgement. Processor: DMD, Board: FP-CPU-002-2, Firmware: 00.88
2016-03-11 15:14:17,570 : INFO : FAST : Connecting to /dev/tty.usbserial-141B at 921600bps
2016-03-11 15:14:20,077 : INFO : FAST : Received ID acknowledgement. Processor: NET, Board: FP-CPU-002-2, Firmware: 00.98
2016-03-11 15:14:21,080 : INFO : FAST : Fast IO Board 00: Model: FP-I/O-3208-2, Firmware: 00.95, Switches: 32, Drivers: 8
2016-03-11 15:14:22,083 : INFO : FAST : Fast IO Board 01: Model: FP-I/O-3208-2, Firmware: 00.95, Switches: 32, Drivers: 8
2016-03-11 15:14:23,088 : INFO : FAST : Fast IO Board 02: Model: FP-I/O-1616-2, Firmware: 00.95, Switches: 16, Drivers: 16
2016-03-11 15:14:28,111 : INFO : DeviceManager : Loading devices...
2016-03-11 15:14:28,154 : ERROR : root : Config validation error: Entry ball_devices:bd_trough:entrance_switch:s_troughEnter is not valid
Traceback (most recent call last):
  File "/Users/gabe/pinball/mpf30/mpf/core/config_validator.py", line 1344, in validate_item
    item = eval(validator.replace('%', "'" + item + "'"))
  File "<string>", line 1, in <module>
  File "/Users/gabe/pinball/mpf30/mpf/core/device_manager.py", line 214, in __getitem__
    return super().__getitem__(self.__class__.lower(key))
  File "/Users/gabe/pinball/mpf30/mpf/core/case_insensitive_dict.py", line 14, in __getitem__
    return super().__getitem__(self.__class__.lower(key))
KeyError: 's_troughenter'

During handling of the above exception, another exception occurred:

Traceback (most recent call last):
  File "/Users/gabe/pinball/mpf30/mpf/commands/core.py", line 135, in __init__
    MachineController(mpf_path, machine_path, vars(args)).run()
  File "/Users/gabe/pinball/mpf30/mpf/core/machine.py", line 130, in __init__
    self.events.process_event_queue()
  File "/Users/gabe/pinball/mpf30/mpf/core/events.py", line 492, in process_event_queue
    **event[3])
  File "/Users/gabe/pinball/mpf30/mpf/core/events.py", line 430, in _process_event
    result = handler[0](**merged_kwargs)
  File "/Users/gabe/pinball/mpf30/mpf/core/device_manager.py", line 52, in _load_device_modules
    self.create_devices(collection_name, config)
  File "/Users/gabe/pinball/mpf30/mpf/core/device_manager.py", line 81, in create_devices
    collection[device] = cls(self.machine, device, config[device], validate)
  File "/Users/gabe/pinball/mpf30/mpf/devices/ball_device.py", line 24, in __init__
    super().__init__(machine, name, config, validate=validate)
  File "/Users/gabe/pinball/mpf30/mpf/core/device.py", line 29, in __init__
    self.config_section, config, self.name)
  File "/Users/gabe/pinball/mpf30/mpf/core/config_validator.py", line 1189, in validate_config
    validation_failure_info=(validation_failure_info, k))
  File "/Users/gabe/pinball/mpf30/mpf/core/config_validator.py", line 1239, in validate_config_item2
    validation_failure_info)
  File "/Users/gabe/pinball/mpf30/mpf/core/config_validator.py", line 1346, in validate_item
    self.validation_error(item, validation_failure_info)
  File "/Users/gabe/pinball/mpf30/mpf/core/config_validator.py", line 1489, in validation_error
    item))
AssertionError: Config validation error: Entry ball_devices:bd_trough:entrance_switch:s_troughEnter is not valid
